place template logic:xor_gate ~29 ~ ~33
place template logic:and_gate ~20 ~ ~33
place template logic:xor_gate ~32 ~ ~43
place template logic:or_gate ~12 ~ ~41
place template logic:and_gate ~21 ~ ~42
setblock ~22 ~-1 ~37 minecraft:pink_wool
setblock ~22 ~0 ~37 minecraft:redstone_wire
setblock ~22 ~-1 ~38 minecraft:pink_wool
setblock ~22 ~0 ~38 minecraft:redstone_wire
setblock ~21 ~-1 ~38 minecraft:pink_wool
setblock ~21 ~0 ~38 minecraft:redstone_wire
setblock ~20 ~-1 ~38 minecraft:pink_wool
setblock ~20 ~0 ~38 minecraft:redstone_wire
setblock ~19 ~-1 ~38 minecraft:pink_wool
setblock ~19 ~0 ~38 minecraft:redstone_wire
setblock ~18 ~-1 ~38 minecraft:pink_wool
setblock ~18 ~0 ~38 minecraft:redstone_wire
setblock ~17 ~-1 ~38 minecraft:pink_wool
setblock ~17 ~0 ~38 minecraft:redstone_wire
setblock ~16 ~-1 ~38 minecraft:pink_wool
setblock ~16 ~0 ~38 minecraft:redstone_wire
setblock ~15 ~-1 ~38 minecraft:pink_wool
setblock ~15 ~0 ~38 minecraft:redstone_wire
setblock ~14 ~-1 ~38 minecraft:pink_wool
setblock ~14 ~0 ~38 minecraft:redstone_wire
setblock ~14 ~-1 ~39 minecraft:pink_wool
setblock ~14 ~0 ~39 minecraft:redstone_wire
setblock ~13 ~-1 ~39 minecraft:pink_wool
setblock ~13 ~0 ~39 minecraft:redstone_wire
setblock ~13 ~-1 ~40 minecraft:pink_wool
setblock ~13 ~0 ~40 minecraft:redstone_wire
setblock ~23 ~-1 ~46 minecraft:pink_wool
setblock ~23 ~0 ~46 minecraft:redstone_wire
setblock ~22 ~-1 ~46 minecraft:pink_wool
setblock ~22 ~0 ~46 minecraft:redstone_wire
setblock ~21 ~-1 ~46 minecraft:pink_wool
setblock ~21 ~0 ~46 minecraft:redstone_wire
setblock ~20 ~-1 ~46 minecraft:pink_wool
setblock ~20 ~0 ~46 minecraft:redstone_wire
setblock ~20 ~-1 ~45 minecraft:pink_wool
setblock ~20 ~0 ~45 minecraft:redstone_wire
setblock ~20 ~-1 ~44 minecraft:pink_wool
setblock ~20 ~0 ~44 minecraft:redstone_wire
setblock ~20 ~-1 ~43 minecraft:pink_wool
setblock ~20 ~0 ~43 minecraft:redstone_wire
setblock ~19 ~-1 ~43 minecraft:pink_wool
setblock ~19 ~0 ~43 minecraft:redstone_wire
setblock ~19 ~-1 ~42 minecraft:pink_wool
setblock ~19 ~0 ~42 minecraft:redstone_wire
setblock ~19 ~-1 ~41 minecraft:pink_wool
setblock ~19 ~0 ~41 minecraft:redstone_wire
setblock ~19 ~-1 ~40 minecraft:pink_wool
setblock ~19 ~0 ~40 minecraft:redstone_wire
setblock ~18 ~-1 ~40 minecraft:pink_wool
setblock ~18 ~0 ~40 minecraft:redstone_wire
setblock ~17 ~-1 ~40 minecraft:pink_wool
setblock ~17 ~0 ~40 minecraft:redstone_wire
setblock ~16 ~-1 ~40 minecraft:pink_wool
setblock ~16 ~0 ~40 minecraft:repeater[facing=east]
setblock ~15 ~-1 ~40 minecraft:pink_wool
setblock ~15 ~0 ~40 minecraft:redstone_wire
setblock ~21 ~0 ~32 minecraft:pink_wool
setblock ~21 ~1 ~32 minecraft:redstone_wire
setblock ~21 ~1 ~31 minecraft:pink_wool
setblock ~21 ~2 ~31 minecraft:redstone_wire
setblock ~22 ~2 ~31 minecraft:pink_wool
setblock ~22 ~3 ~31 minecraft:redstone_wire
setblock ~23 ~3 ~31 minecraft:pink_wool
setblock ~23 ~4 ~31 minecraft:redstone_wire
setblock ~24 ~2 ~31 minecraft:pink_wool
setblock ~24 ~3 ~31 minecraft:redstone_wire
setblock ~25 ~1 ~31 minecraft:pink_wool
setblock ~25 ~2 ~31 minecraft:redstone_wire
setblock ~25 ~0 ~32 minecraft:pink_wool
setblock ~25 ~1 ~32 minecraft:redstone_wire
setblock ~26 ~-1 ~32 minecraft:pink_wool
setblock ~26 ~0 ~32 minecraft:redstone_wire
setblock ~27 ~-1 ~32 minecraft:pink_wool
setblock ~27 ~0 ~32 minecraft:redstone_wire
setblock ~28 ~-1 ~32 minecraft:pink_wool
setblock ~28 ~0 ~32 minecraft:redstone_wire
setblock ~29 ~-1 ~32 minecraft:pink_wool
setblock ~29 ~0 ~32 minecraft:redstone_wire
setblock ~30 ~-1 ~32 minecraft:pink_wool
setblock ~30 ~0 ~32 minecraft:redstone_wire
setblock ~23 ~-1 ~32 minecraft:pink_wool
setblock ~23 ~0 ~32 minecraft:redstone_wire
setblock ~23 ~-1 ~31 minecraft:pink_wool
setblock ~23 ~0 ~31 minecraft:redstone_wire
setblock ~23 ~-1 ~30 minecraft:pink_wool
setblock ~23 ~0 ~30 minecraft:redstone_wire
setblock ~24 ~-1 ~30 minecraft:pink_wool
setblock ~24 ~0 ~30 minecraft:redstone_wire
setblock ~25 ~-1 ~30 minecraft:pink_wool
setblock ~25 ~0 ~30 minecraft:redstone_wire
setblock ~26 ~-1 ~30 minecraft:pink_wool
setblock ~26 ~0 ~30 minecraft:redstone_wire
setblock ~27 ~-1 ~30 minecraft:pink_wool
setblock ~27 ~0 ~30 minecraft:redstone_wire
setblock ~28 ~-1 ~30 minecraft:pink_wool
setblock ~28 ~0 ~30 minecraft:redstone_wire
setblock ~29 ~-1 ~30 minecraft:pink_wool
setblock ~29 ~0 ~30 minecraft:redstone_wire
setblock ~30 ~-1 ~30 minecraft:pink_wool
setblock ~30 ~0 ~30 minecraft:redstone_wire
setblock ~31 ~-1 ~30 minecraft:pink_wool
setblock ~31 ~0 ~30 minecraft:redstone_wire
setblock ~31 ~-1 ~31 minecraft:pink_wool
setblock ~31 ~0 ~31 minecraft:redstone_wire
setblock ~32 ~-1 ~31 minecraft:pink_wool
setblock ~32 ~0 ~31 minecraft:redstone_wire
setblock ~30 ~-1 ~30 minecraft:pink_wool
setblock ~30 ~0 ~30 minecraft:repeater[facing=west]
setblock ~31 ~-1 ~39 minecraft:pink_wool
setblock ~31 ~0 ~39 minecraft:redstone_wire
setblock ~31 ~-1 ~40 minecraft:pink_wool
setblock ~31 ~0 ~40 minecraft:redstone_wire
setblock ~31 ~-1 ~41 minecraft:pink_wool
setblock ~31 ~0 ~41 minecraft:redstone_wire
setblock ~31 ~-1 ~42 minecraft:pink_wool
setblock ~31 ~0 ~42 minecraft:redstone_wire
setblock ~32 ~-1 ~42 minecraft:pink_wool
setblock ~32 ~0 ~42 minecraft:redstone_wire
setblock ~33 ~-1 ~42 minecraft:pink_wool
setblock ~33 ~0 ~42 minecraft:redstone_wire
setblock ~30 ~-1 ~39 minecraft:pink_wool
setblock ~30 ~0 ~39 minecraft:redstone_wire
setblock ~29 ~-1 ~39 minecraft:pink_wool
setblock ~29 ~0 ~39 minecraft:redstone_wire
setblock ~28 ~-1 ~39 minecraft:pink_wool
setblock ~28 ~0 ~39 minecraft:redstone_wire
setblock ~27 ~-1 ~39 minecraft:pink_wool
setblock ~27 ~0 ~39 minecraft:redstone_wire
setblock ~26 ~-1 ~39 minecraft:pink_wool
setblock ~26 ~0 ~39 minecraft:redstone_wire
setblock ~25 ~-1 ~39 minecraft:pink_wool
setblock ~25 ~0 ~39 minecraft:redstone_wire
setblock ~24 ~-1 ~39 minecraft:pink_wool
setblock ~24 ~0 ~39 minecraft:redstone_wire
setblock ~23 ~-1 ~39 minecraft:pink_wool
setblock ~23 ~0 ~39 minecraft:redstone_wire
setblock ~23 ~-1 ~40 minecraft:pink_wool
setblock ~23 ~0 ~40 minecraft:redstone_wire
setblock ~22 ~-1 ~40 minecraft:pink_wool
setblock ~22 ~0 ~40 minecraft:redstone_wire
setblock ~22 ~-1 ~41 minecraft:pink_wool
setblock ~22 ~0 ~41 minecraft:redstone_wire
setblock ~24 ~0 ~41 minecraft:pink_wool
setblock ~24 ~1 ~41 minecraft:redstone_wire
setblock ~25 ~1 ~41 minecraft:pink_wool
setblock ~25 ~2 ~41 minecraft:redstone_wire
setblock ~26 ~2 ~41 minecraft:pink_wool
setblock ~26 ~3 ~41 minecraft:redstone_wire
setblock ~27 ~3 ~41 minecraft:pink_wool
setblock ~27 ~4 ~41 minecraft:redstone_wire
setblock ~28 ~3 ~41 minecraft:pink_wool
setblock ~28 ~4 ~41 minecraft:redstone_wire
setblock ~29 ~3 ~41 minecraft:pink_wool
setblock ~29 ~4 ~41 minecraft:redstone_wire
setblock ~30 ~3 ~41 minecraft:pink_wool
setblock ~30 ~4 ~41 minecraft:redstone_wire
setblock ~31 ~3 ~41 minecraft:pink_wool
setblock ~31 ~4 ~41 minecraft:redstone_wire
setblock ~32 ~3 ~41 minecraft:pink_wool
setblock ~32 ~4 ~41 minecraft:redstone_wire
setblock ~33 ~3 ~41 minecraft:pink_wool
setblock ~33 ~4 ~41 minecraft:redstone_wire
setblock ~34 ~2 ~41 minecraft:pink_wool
setblock ~34 ~3 ~41 minecraft:redstone_wire
setblock ~35 ~1 ~41 minecraft:pink_wool
setblock ~35 ~2 ~41 minecraft:redstone_wire
setblock ~35 ~0 ~42 minecraft:pink_wool
setblock ~35 ~1 ~42 minecraft:redstone_wire
